Workbook

Sheet Tracker
A1: # | B1: Тиждень | C1: Завдання | D1: Хто | E1: Статус | F1: Пріоритет | G1: Нотатки
B2: Готово (Setup)
A3: 1 | B3: Setup | C3: Docker-середовище (nginx + PHP 8.3 + MariaDB + Redis + MailHog) | D3: Dev 1 | E3: Done | F3: High
A4: 2 | B4: Setup | C4: composer.json з усіма модулями | D4: Dev 1 | E4: Done | F4: High
A5: 3 | B5: Setup | C5: Скрипти install.sh / start.sh | D5: Dev 1 | E5: Done | F5: High
A6: 4 | B6: Setup | C6: .gitattributes / .gitignore / .env.example | D6: Dev 1 | E6: Done | F6: Medium
A7: 5 | B7: Setup | C7: Git-репо + GitHub push | D7: Dev 1 | E7: Done | F7: High
A8: 6 | B8: Setup | C8: PROJECT_PLAN.md — повний технічний план | D8: Dev 1 | E8: Done | F8: High
A9: 7 | B9: Setup | C9: Drupal встановлено на localhost | D9: Dev 1 | E9: Done | F9: High
B10: Тиждень 1 — Спільний фундамент
A11: 8 | B11: Тижд.1 | C11: Включити та налаштувати всі модулі | D11: Разом | E11: Not Started | F11: High
A12: 9 | B12: Тижд.1 | C12: Config export/import воркфлоу | D12: Разом | E12: Not Started | F12: High
A13: 10 | B13: Тижд.1 | C13: Таксономія product_category | D13: Разом | E13: Not Started | F13: High
A14: 11 | B14: Тижд.1 | C14: Таксономія industry_tax | D14: Разом | E14: Not Started | F14: High
A15: 12 | B15: Тижд.1 | C15: Таксономія state_province (50 штатів + 13 провінцій) | D15: Разом | E15: Not Started | F15: Medium
A16: 13 | B16: Тижд.1 | C16: 13 стилів зображень (за PROJECT_PLAN §7.7) | D16: Разом | E16: Not Started | F16: High
A17: 14 | B17: Тижд.1 | C17: Головне меню — повна структура | D17: Разом | E17: Not Started | F17: High
A18: 15 | B18: Тижд.1 | C18: Тема bearcom — каркас (info.yml, libraries.yml) | D18: Разом | E18: Not Started | F18: High
A19: 16 | B19: Тижд.1 | C19: CSS-змінні, ресет, типографіка H1-H5, сітка | D19: Разом | E19: Not Started | F19: High
A20: 17 | B20: Тижд.1 | C20: Хедер — top bar + навігація + Contact Us | D20: Разом | E20: Not Started | F20: High
A21: 18 | B21: Тижд.1 | C21: Мега-меню — ховер-дропдауни + JS | D21: Разом | E21: Not Started | F21: High
A22: 19 | B22: Тижд.1 | C22: Пошук в хедері | D22: Разом | E22: Not Started | F22: Medium
... A25: 22 | B25: Тижд.1 | C25: drush cex → git push (зафіксувати базу) | D25: Разом | E25: Not Started | F25: High
B26: Тиждень 2 — Dev 1: Головна / Dev 2: Індустрії
A27: 23 | B27: Тижд.2 | C27: CT flexible_page з усіма полями | D27: Dev 1 | E27: Not Started | F27: High
A28: 24 | B28: Тижд.2 | C28: Параграфи: hero_banner, cta_block, card_grid, card_item | D28: Dev 1 | E28: Not Started | F28: High
A29: 25 | B29: Тижд.2 | C29: Параграфи: stats_counter, stat_item, rentals_connected | D29: Dev 1 | E29: Not Started | F29: High
A30: 26 | B30: Тижд.2 | C30: Параграфи: guided_journey, gj_tab, checklist_item | D30: Dev 1 | E30: Not Started | F30: High
A31: 27 | B31: Тижд.2 | C31: Нода Homepage → front page | D31: Dev 1 | E31: Not Started | F31: High
A32: 28 | B32: Тижд.2 | C32: Шаблони: Hero, CTA, Card Grid, Stats, Guided Journey, Rentals | D32: Dev 1 | E32: Not Started | F32: High
A33: 29 | B33: Тижд.2 | C33: JS: stats-counter.js, tabs.js | D33: Dev 1 | E33: Not Started | F33: Medium
A34: 30 | B34: Тижд.2 | C34: ЗІБРАТИ ГОЛОВНУ СТОРІНКУ | D34: Dev 1 | E34: Not Started | F34: High
A35: 31 | B35: Тижд.2 | C35: CT industry (icon, hero, body, solutions, cta) | D35: Dev 2 | E35: Not Started | F35: High
A36: 32 | B36: Тижд.2 | C36: Параграф content_block (title, body, image, layout L/R) | D36: Dev 2 | E36: Not Started | F36: High
A37: 33 | B37: Тижд.2 | C37: View industries_listing (Grid 3x3) | D37: Dev 2 | E37: Not Started | F37: Medium
A38: 34 | B38: Тижд.2 | C38: 3 тестові індустрії | D38: Dev 2 | E38: Not Started | F38: Medium
... A40: 36 | B40: Тижд.2 | C40: ЗІБРАТИ: батьківську індустрій + сторінку індустрії | D40: Dev 2 | E40: Not Started | F40: High
B41: Тиждень 3 — Dev 1: Каталог / Dev 2: Сервіс
A42: 37 | B42: Тижд.3 | C42: CT product з усіма полями | D42: Dev 1 | E42: Not Started | F42: High
A43: 38 | B43: Тижд.3 | C43: View products_listing (BEF + AJAX + pager) | D43: Dev 1 | E43: Not Started | F43: High
...

Sheet Progress
B1: Всього | C1: Готово | D1: % Готово
A2: Setup | B2: =COUNTIF(Tracker!B:B,"Setup") | C2: =COUNTIFS(Tracker!B:B,"Setup",Tracker!E:E,"Done") | D2: =IF(B1=0,0,C1/B1)
A3: Тиждень 1 | B3: =COUNTIF(Tracker!B:B,"Тижд.1") | C3: =COUNTIFS(Tracker!B:B,"Тижд.1",Tracker!E:E,"Done") | D3: =IF(B2=0,0,C2/B2)
A4: Тиждень 2 | B4: =COUNTIF(Tracker!B:B,"Тижд.2") | C4: =COUNTIFS(Tracker!B:B,"Тижд.2",Tracker!E:E,"Done") | D4: =IF(B3=0,0,C3/B3)
A5: Тиждень 3 | B5: =COUNTIF(Tracker!B:B,"Тижд.3") | C5: =COUNTIFS(Tracker!B:B,"Тижд.3",Tracker!E:E,"Done") | D5: =IF(B4=0,0,C4/B4)
A6: Тиждень 4 | B6: =COUNTIF(Tracker!B:B,"Тижд.4") | C6: =COUNTIFS(Tracker!B:B,"Тижд.4",Tracker!E:E,"Done") | D6: =IF(B5=0,0,C5/B5)
A7: Тиждень 5 | B7: =COUNTIF(Tracker!B:B,"Тижд.5") | C7: =COUNTIFS(Tracker!B:B,"Тижд.5",Tracker!E:E,"Done") | D7: =IF(B6=0,0,C6/B6)
A8: Тиждень 6 | B8: =COUNTIF(Tracker!B:B,"Тижд.6") | C8: =COUNTIFS(Tracker!B:B,"Тижд.6",Tracker!E:E,"Done") | D8: =IF(B7=0,0,C7/B7)
A9: Тиждень 7 | B9: =COUNTIF(Tracker!B:B,"Тижд.7") | C9: =COUNTIFS(Tracker!B:B,"Тижд.7",Tracker!E:E,"Done") | D9: =IF(B8=0,0,C8/B8)
A10: Тижні 8-9 | B10: =COUNTIF(Tracker!B:B,"Тижд.8-9") | C10: =COUNTIFS(Tracker!B:B,"Тижд.8-9",Tracker!E:E,"Done") | D10: =IF(B9=0,0,C9/B9)
A11: Тиждень 10 | B11: =COUNTIF(Tracker!B:B,"Тижд.10") | C11: =COUNTIFS(Tracker!B:B,"Тижд.10",Tracker!E:E,"Done") | D11: =IF(B10=0,0,C10/B10)
A12: РАЗОМ | B12: =SUM(B2:B11) | C12: =SUM(C2:C11) | D12: =IF(B12=0,0,C12/B12)
